[2023-02-16T07:48:39.609+0000] {taskinstance.py:1083} INFO - Dependencies all met for <TaskInstance: dag_e2e_etl_v02.t1a_read_csv_from_web manual__2023-02-16T07:48:37.969808+00:00 [queued]>
[2023-02-16T07:48:39.673+0000] {taskinstance.py:1083} INFO - Dependencies all met for <TaskInstance: dag_e2e_etl_v02.t1a_read_csv_from_web manual__2023-02-16T07:48:37.969808+00:00 [queued]>
[2023-02-16T07:48:39.675+0000] {taskinstance.py:1279} INFO - 
--------------------------------------------------------------------------------
[2023-02-16T07:48:39.679+0000] {taskinstance.py:1280} INFO - Starting attempt 1 of 1
[2023-02-16T07:48:39.687+0000] {taskinstance.py:1281} INFO - 
--------------------------------------------------------------------------------
[2023-02-16T07:48:39.714+0000] {taskinstance.py:1300} INFO - Executing <Task(PythonOperator): t1a_read_csv_from_web> on 2023-02-16 07:48:37.969808+00:00
[2023-02-16T07:48:39.756+0000] {standard_task_runner.py:55} INFO - Started process 33844 to run task
[2023-02-16T07:48:39.767+0000] {standard_task_runner.py:82} INFO - Running: ['***', 'tasks', 'run', 'dag_e2e_etl_v02', 't1a_read_csv_from_web', 'manual__2023-02-16T07:48:37.969808+00:00', '--job-id', '143', '--raw', '--subdir', 'DAGS_FOLDER/dag_e2e_etl.py', '--cfg-path', '/tmp/tmpdeg67_s2']
[2023-02-16T07:48:39.770+0000] {standard_task_runner.py:83} INFO - Job 143: Subtask t1a_read_csv_from_web
[2023-02-16T07:48:39.939+0000] {task_command.py:388} INFO - Running <TaskInstance: dag_e2e_etl_v02.t1a_read_csv_from_web manual__2023-02-16T07:48:37.969808+00:00 [running]> on host 20eb5e5814e6
[2023-02-16T07:48:40.821+0000] {taskinstance.py:1509} INFO - Exporting the following env vars:
AIRFLOW_CTX_DAG_OWNER=***
AIRFLOW_CTX_DAG_ID=dag_e2e_etl_v02
AIRFLOW_CTX_TASK_ID=t1a_read_csv_from_web
AIRFLOW_CTX_EXECUTION_DATE=2023-02-16T07:48:37.969808+00:00
AIRFLOW_CTX_TRY_NUMBER=1
AIRFLOW_CTX_DAG_RUN_ID=manual__2023-02-16T07:48:37.969808+00:00
[2023-02-16T07:48:42.127+0000] {taskinstance.py:1768} ERROR - Task failed with exception
Traceback (most recent call last):
  File "/home/airflow/.local/lib/python3.7/site-packages/airflow/operators/python.py", line 175, in execute
    return_value = self.execute_callable()
  File "/home/airflow/.local/lib/python3.7/site-packages/airflow/operators/python.py", line 192, in execute_callable
    return self.python_callable(*self.op_args, **self.op_kwargs)
  File "/opt/airflow/dags/dag_e2e_etl.py", line 25, in t1a_read_csv_from_web
    write_file_to_local('t1a.csv', df)
  File "/opt/airflow/dags/dag_e2e_etl.py", line 17, in write_file_to_local
    path  = os.path.dirname(os.path.abspath(__file__))
NameError: name 'os' is not defined
[2023-02-16T07:48:42.153+0000] {taskinstance.py:1323} INFO - Marking task as FAILED. dag_id=dag_e2e_etl_v02, task_id=t1a_read_csv_from_web, execution_date=20230216T074837, start_date=20230216T074839, end_date=20230216T074842
[2023-02-16T07:48:42.166+0000] {standard_task_runner.py:105} ERROR - Failed to execute job 143 for task t1a_read_csv_from_web (name 'os' is not defined; 33844)
[2023-02-16T07:48:42.273+0000] {local_task_job.py:208} INFO - Task exited with return code 1
[2023-02-16T07:48:42.307+0000] {taskinstance.py:2578} INFO - 0 downstream tasks scheduled from follow-on schedule check
