[2023-02-15T13:00:41.890+0000] {taskinstance.py:1083} INFO - Dependencies all met for <TaskInstance: dag_e2e_etl_v01.t1_read_csv scheduled__2023-02-14T00:00:00+00:00 [queued]>
[2023-02-15T13:00:41.897+0000] {taskinstance.py:1083} INFO - Dependencies all met for <TaskInstance: dag_e2e_etl_v01.t1_read_csv scheduled__2023-02-14T00:00:00+00:00 [queued]>
[2023-02-15T13:00:41.904+0000] {taskinstance.py:1279} INFO - 
--------------------------------------------------------------------------------
[2023-02-15T13:00:41.923+0000] {taskinstance.py:1280} INFO - Starting attempt 1 of 1
[2023-02-15T13:00:41.924+0000] {taskinstance.py:1281} INFO - 
--------------------------------------------------------------------------------
[2023-02-15T13:00:41.942+0000] {taskinstance.py:1300} INFO - Executing <Task(PythonOperator): t1_read_csv> on 2023-02-14 00:00:00+00:00
[2023-02-15T13:00:41.954+0000] {standard_task_runner.py:55} INFO - Started process 7071 to run task
[2023-02-15T13:00:41.965+0000] {standard_task_runner.py:82} INFO - Running: ['***', 'tasks', 'run', 'dag_e2e_etl_v01', 't1_read_csv', 'scheduled__2023-02-14T00:00:00+00:00', '--job-id', '119', '--raw', '--subdir', 'DAGS_FOLDER/dag_e2e_etl.py', '--cfg-path', '/tmp/tmpb4d4va9f']
[2023-02-15T13:00:41.970+0000] {standard_task_runner.py:83} INFO - Job 119: Subtask t1_read_csv
[2023-02-15T13:00:42.048+0000] {task_command.py:388} INFO - Running <TaskInstance: dag_e2e_etl_v01.t1_read_csv scheduled__2023-02-14T00:00:00+00:00 [running]> on host 20eb5e5814e6
[2023-02-15T13:00:42.536+0000] {taskinstance.py:1509} INFO - Exporting the following env vars:
AIRFLOW_CTX_DAG_OWNER=***
AIRFLOW_CTX_DAG_ID=dag_e2e_etl_v01
AIRFLOW_CTX_TASK_ID=t1_read_csv
AIRFLOW_CTX_EXECUTION_DATE=2023-02-14T00:00:00+00:00
AIRFLOW_CTX_TRY_NUMBER=1
AIRFLOW_CTX_DAG_RUN_ID=scheduled__2023-02-14T00:00:00+00:00
[2023-02-15T13:00:42.542+0000] {taskinstance.py:1768} ERROR - Task failed with exception
Traceback (most recent call last):
  File "/home/airflow/.local/lib/python3.7/site-packages/airflow/operators/python.py", line 175, in execute
    return_value = self.execute_callable()
  File "/home/airflow/.local/lib/python3.7/site-packages/airflow/operators/python.py", line 192, in execute_callable
    return self.python_callable(*self.op_args, **self.op_kwargs)
  File "/opt/airflow/dags/dag_e2e_etl.py", line 18, in t1_read_csv
    response =  requests.get(url, error_bad_lines=False)
NameError: name 'requests' is not defined
[2023-02-15T13:00:42.571+0000] {taskinstance.py:1323} INFO - Marking task as FAILED. dag_id=dag_e2e_etl_v01, task_id=t1_read_csv, execution_date=20230214T000000, start_date=20230215T130041, end_date=20230215T130042
[2023-02-15T13:00:42.629+0000] {standard_task_runner.py:105} ERROR - Failed to execute job 119 for task t1_read_csv (name 'requests' is not defined; 7071)
[2023-02-15T13:00:42.707+0000] {local_task_job.py:208} INFO - Task exited with return code 1
[2023-02-15T13:00:42.821+0000] {taskinstance.py:2578} INFO - 0 downstream tasks scheduled from follow-on schedule check
