[2023-02-23T07:53:18.075+0000] {taskinstance.py:1083} INFO - Dependencies all met for <TaskInstance: csv_from_s3_to_s3_v01.ETL manual__2023-02-23T07:53:16.289429+00:00 [queued]>
[2023-02-23T07:53:18.081+0000] {taskinstance.py:1083} INFO - Dependencies all met for <TaskInstance: csv_from_s3_to_s3_v01.ETL manual__2023-02-23T07:53:16.289429+00:00 [queued]>
[2023-02-23T07:53:18.082+0000] {taskinstance.py:1279} INFO - 
--------------------------------------------------------------------------------
[2023-02-23T07:53:18.082+0000] {taskinstance.py:1280} INFO - Starting attempt 1 of 1
[2023-02-23T07:53:18.083+0000] {taskinstance.py:1281} INFO - 
--------------------------------------------------------------------------------
[2023-02-23T07:53:18.090+0000] {taskinstance.py:1300} INFO - Executing <Task(PythonOperator): ETL> on 2023-02-23 07:53:16.289429+00:00
[2023-02-23T07:53:18.095+0000] {standard_task_runner.py:55} INFO - Started process 16786 to run task
[2023-02-23T07:53:18.099+0000] {standard_task_runner.py:82} INFO - Running: ['***', 'tasks', 'run', 'csv_from_s3_to_s3_v01', 'ETL', 'manual__2023-02-23T07:53:16.289429+00:00', '--job-id', '224', '--raw', '--subdir', 'DAGS_FOLDER/dag_cleaning_via_s3.py', '--cfg-path', '/tmp/tmp9dhxqbp0']
[2023-02-23T07:53:18.102+0000] {standard_task_runner.py:83} INFO - Job 224: Subtask ETL
[2023-02-23T07:53:18.157+0000] {task_command.py:388} INFO - Running <TaskInstance: csv_from_s3_to_s3_v01.ETL manual__2023-02-23T07:53:16.289429+00:00 [running]> on host e29b8426fc8e
[2023-02-23T07:53:18.241+0000] {taskinstance.py:1509} INFO - Exporting the following env vars:
AIRFLOW_CTX_DAG_OWNER=***
AIRFLOW_CTX_DAG_ID=csv_from_s3_to_s3_v01
AIRFLOW_CTX_TASK_ID=ETL
AIRFLOW_CTX_EXECUTION_DATE=2023-02-23T07:53:16.289429+00:00
AIRFLOW_CTX_TRY_NUMBER=1
AIRFLOW_CTX_DAG_RUN_ID=manual__2023-02-23T07:53:16.289429+00:00
[2023-02-23T07:53:18.243+0000] {taskinstance.py:1768} ERROR - Task failed with exception
Traceback (most recent call last):
  File "/home/airflow/.local/lib/python3.7/site-packages/airflow/operators/python.py", line 175, in execute
    return_value = self.execute_callable()
  File "/home/airflow/.local/lib/python3.7/site-packages/airflow/operators/python.py", line 192, in execute_callable
    return self.python_callable(*self.op_args, **self.op_kwargs)
  File "/opt/airflow/dags/dag_cleaning_via_s3.py", line 64, in RunETL
    df = self.get_file_from_s3()
  File "/opt/airflow/dags/dag_cleaning_via_s3.py", line 32, in get_file_from_s3
    s3_hook = S3Hook(self.AWS_CONN_ID)
AttributeError: 'EtlJob' object has no attribute 'AWS_CONN_ID'
[2023-02-23T07:53:18.254+0000] {taskinstance.py:1323} INFO - Marking task as FAILED. dag_id=csv_from_s3_to_s3_v01, task_id=ETL, execution_date=20230223T075316, start_date=20230223T075318, end_date=20230223T075318
[2023-02-23T07:53:18.269+0000] {standard_task_runner.py:105} ERROR - Failed to execute job 224 for task ETL ('EtlJob' object has no attribute 'AWS_CONN_ID'; 16786)
[2023-02-23T07:53:18.312+0000] {local_task_job.py:208} INFO - Task exited with return code 1
[2023-02-23T07:53:18.331+0000] {taskinstance.py:2578} INFO - 0 downstream tasks scheduled from follow-on schedule check
