[2023-02-22T16:24:31.440+0000] {taskinstance.py:1083} INFO - Dependencies all met for <TaskInstance: csv_from_s3_to_s3_v01.ETL manual__2023-02-22T16:24:29.635423+00:00 [queued]>
[2023-02-22T16:24:31.448+0000] {taskinstance.py:1083} INFO - Dependencies all met for <TaskInstance: csv_from_s3_to_s3_v01.ETL manual__2023-02-22T16:24:29.635423+00:00 [queued]>
[2023-02-22T16:24:31.450+0000] {taskinstance.py:1279} INFO - 
--------------------------------------------------------------------------------
[2023-02-22T16:24:31.451+0000] {taskinstance.py:1280} INFO - Starting attempt 1 of 1
[2023-02-22T16:24:31.451+0000] {taskinstance.py:1281} INFO - 
--------------------------------------------------------------------------------
[2023-02-22T16:24:31.461+0000] {taskinstance.py:1300} INFO - Executing <Task(PythonOperator): ETL> on 2023-02-22 16:24:29.635423+00:00
[2023-02-22T16:24:31.474+0000] {standard_task_runner.py:55} INFO - Started process 237 to run task
[2023-02-22T16:24:31.493+0000] {standard_task_runner.py:82} INFO - Running: ['***', 'tasks', 'run', 'csv_from_s3_to_s3_v01', 'ETL', 'manual__2023-02-22T16:24:29.635423+00:00', '--job-id', '217', '--raw', '--subdir', 'DAGS_FOLDER/dag_cleaning_via_s3.py', '--cfg-path', '/tmp/tmpplpy_arw']
[2023-02-22T16:24:31.496+0000] {standard_task_runner.py:83} INFO - Job 217: Subtask ETL
[2023-02-22T16:24:31.644+0000] {task_command.py:388} INFO - Running <TaskInstance: csv_from_s3_to_s3_v01.ETL manual__2023-02-22T16:24:29.635423+00:00 [running]> on host e29b8426fc8e
[2023-02-22T16:24:31.741+0000] {taskinstance.py:1509} INFO - Exporting the following env vars:
AIRFLOW_CTX_DAG_OWNER=***
AIRFLOW_CTX_DAG_ID=csv_from_s3_to_s3_v01
AIRFLOW_CTX_TASK_ID=ETL
AIRFLOW_CTX_EXECUTION_DATE=2023-02-22T16:24:29.635423+00:00
AIRFLOW_CTX_TRY_NUMBER=1
AIRFLOW_CTX_DAG_RUN_ID=manual__2023-02-22T16:24:29.635423+00:00
[2023-02-22T16:24:31.744+0000] {logging_mixin.py:137} INFO - file name titanic.csv
[2023-02-22T16:24:31.755+0000] {base.py:73} INFO - Using connection ID 'AWS' for task execution.
[2023-02-22T16:24:31.756+0000] {connection_wrapper.py:334} INFO - AWS Connection (conn_id='AWS', conn_type='aws') credentials retrieved from login and password.
[2023-02-22T16:24:32.805+0000] {taskinstance.py:1768} ERROR - Task failed with exception
Traceback (most recent call last):
  File "/home/airflow/.local/lib/python3.7/site-packages/airflow/operators/python.py", line 175, in execute
    return_value = self.execute_callable()
  File "/home/airflow/.local/lib/python3.7/site-packages/airflow/operators/python.py", line 192, in execute_callable
    return self.python_callable(*self.op_args, **self.op_kwargs)
  File "/opt/airflow/dags/dag_cleaning_via_s3.py", line 80, in ETL
    aws_conn_id=aws_conn_id)
  File "/opt/airflow/dags/dag_cleaning_via_s3.py", line 59, in put_file_to_s3
    file_name=file_name
  File "/home/airflow/.local/lib/python3.7/site-packages/airflow/providers/amazon/aws/hooks/s3.py", line 84, in wrapper
    bound_args = function_signature.bind(*args, **kwargs)
  File "/usr/local/lib/python3.7/inspect.py", line 3015, in bind
    return args[0]._bind(args[1:], kwargs)
  File "/usr/local/lib/python3.7/inspect.py", line 3006, in _bind
    arg=next(iter(kwargs))))
TypeError: got an unexpected keyword argument 'file_name'
[2023-02-22T16:24:32.839+0000] {taskinstance.py:1323} INFO - Marking task as FAILED. dag_id=csv_from_s3_to_s3_v01, task_id=ETL, execution_date=20230222T162429, start_date=20230222T162431, end_date=20230222T162432
[2023-02-22T16:24:32.867+0000] {standard_task_runner.py:105} ERROR - Failed to execute job 217 for task ETL (got an unexpected keyword argument 'file_name'; 237)
[2023-02-22T16:24:32.967+0000] {local_task_job.py:208} INFO - Task exited with return code 1
[2023-02-22T16:24:33.032+0000] {taskinstance.py:2578} INFO - 0 downstream tasks scheduled from follow-on schedule check
