[2023-02-14T13:33:00.891+0000] {taskinstance.py:1083} INFO - Dependencies all met for <TaskInstance: postgres_operator_dag_v1.2.insert_into_postgres_table manual__2023-02-14T13:32:59.193967+00:00 [queued]>
[2023-02-14T13:33:00.897+0000] {taskinstance.py:1083} INFO - Dependencies all met for <TaskInstance: postgres_operator_dag_v1.2.insert_into_postgres_table manual__2023-02-14T13:32:59.193967+00:00 [queued]>
[2023-02-14T13:33:00.897+0000] {taskinstance.py:1279} INFO - 
--------------------------------------------------------------------------------
[2023-02-14T13:33:00.898+0000] {taskinstance.py:1280} INFO - Starting attempt 1 of 6
[2023-02-14T13:33:00.898+0000] {taskinstance.py:1281} INFO - 
--------------------------------------------------------------------------------
[2023-02-14T13:33:00.906+0000] {taskinstance.py:1300} INFO - Executing <Task(PostgresOperator): insert_into_postgres_table> on 2023-02-14 13:32:59.193967+00:00
[2023-02-14T13:33:00.910+0000] {standard_task_runner.py:55} INFO - Started process 5429 to run task
[2023-02-14T13:33:00.913+0000] {standard_task_runner.py:82} INFO - Running: ['***', 'tasks', 'run', 'postgres_operator_dag_v1.2', 'insert_into_postgres_table', 'manual__2023-02-14T13:32:59.193967+00:00', '--job-id', '67', '--raw', '--subdir', 'DAGS_FOLDER/dag_with_postgres_operator.py', '--cfg-path', '/tmp/tmpod9xc0b4']
[2023-02-14T13:33:00.915+0000] {standard_task_runner.py:83} INFO - Job 67: Subtask insert_into_postgres_table
[2023-02-14T13:33:00.962+0000] {task_command.py:388} INFO - Running <TaskInstance: postgres_operator_dag_v1.2.insert_into_postgres_table manual__2023-02-14T13:32:59.193967+00:00 [running]> on host 01550fe0586b
[2023-02-14T13:33:00.984+0000] {abstractoperator.py:613} ERROR - Exception rendering Jinja template for task 'insert_into_postgres_table', field 'sql'. Template: '\n            INSERT INTO dag_runs (dt, dag_id) values({{dt}}, {{dag.dag_id)\n        '
Traceback (most recent call last):
  File "/home/airflow/.local/lib/python3.7/site-packages/airflow/models/abstractoperator.py", line 606, in _do_render_template_fields
    seen_oids,
  File "/home/airflow/.local/lib/python3.7/site-packages/airflow/models/abstractoperator.py", line 659, in render_template
    template = jinja_env.from_string(value)
  File "/home/airflow/.local/lib/python3.7/site-packages/jinja2/environment.py", line 1105, in from_string
    return cls.from_code(self, self.compile(source), gs, None)
  File "/home/airflow/.local/lib/python3.7/site-packages/jinja2/environment.py", line 768, in compile
    self.handle_exception(source=source_hint)
  File "/home/airflow/.local/lib/python3.7/site-packages/jinja2/environment.py", line 936, in handle_exception
    raise rewrite_traceback_stack(source=source)
  File "<unknown>", line 2, in template
jinja2.exceptions.TemplateSyntaxError: unexpected ')'
[2023-02-14T13:33:00.987+0000] {taskinstance.py:1768} ERROR - Task failed with exception
Traceback (most recent call last):
  File "/home/airflow/.local/lib/python3.7/site-packages/airflow/models/taskinstance.py", line 1374, in _run_raw_task
    self._execute_task_with_callbacks(context, test_mode)
  File "/home/airflow/.local/lib/python3.7/site-packages/airflow/models/taskinstance.py", line 1493, in _execute_task_with_callbacks
    task_orig = self.render_templates(context=context)
  File "/home/airflow/.local/lib/python3.7/site-packages/airflow/models/taskinstance.py", line 2115, in render_templates
    original_task.render_template_fields(context)
  File "/home/airflow/.local/lib/python3.7/site-packages/airflow/models/baseoperator.py", line 1179, in render_template_fields
    self._do_render_template_fields(self, self.template_fields, context, jinja_env, set())
  File "/home/airflow/.local/lib/python3.7/site-packages/airflow/utils/session.py", line 75, in wrapper
    return func(*args, session=session, **kwargs)
  File "/home/airflow/.local/lib/python3.7/site-packages/airflow/models/abstractoperator.py", line 606, in _do_render_template_fields
    seen_oids,
  File "/home/airflow/.local/lib/python3.7/site-packages/airflow/models/abstractoperator.py", line 659, in render_template
    template = jinja_env.from_string(value)
  File "/home/airflow/.local/lib/python3.7/site-packages/jinja2/environment.py", line 1105, in from_string
    return cls.from_code(self, self.compile(source), gs, None)
  File "/home/airflow/.local/lib/python3.7/site-packages/jinja2/environment.py", line 768, in compile
    self.handle_exception(source=source_hint)
  File "/home/airflow/.local/lib/python3.7/site-packages/jinja2/environment.py", line 936, in handle_exception
    raise rewrite_traceback_stack(source=source)
  File "<unknown>", line 2, in template
jinja2.exceptions.TemplateSyntaxError: unexpected ')'
[2023-02-14T13:33:01.000+0000] {taskinstance.py:1323} INFO - Marking task as UP_FOR_RETRY. dag_id=postgres_operator_dag_v1.2, task_id=insert_into_postgres_table, execution_date=20230214T133259, start_date=20230214T133300, end_date=20230214T133300
[2023-02-14T13:33:01.008+0000] {standard_task_runner.py:105} ERROR - Failed to execute job 67 for task insert_into_postgres_table (unexpected ')'; 5429)
[2023-02-14T13:33:01.047+0000] {local_task_job.py:208} INFO - Task exited with return code 1
[2023-02-14T13:33:01.062+0000] {taskinstance.py:2578} INFO - 0 downstream tasks scheduled from follow-on schedule check
