[2023-02-16T07:48:39.608+0000] {taskinstance.py:1083} INFO - Dependencies all met for <TaskInstance: dag_e2e_etl_v02.t1b_read_csv_from_local manual__2023-02-16T07:48:37.969808+00:00 [queued]>
[2023-02-16T07:48:39.673+0000] {taskinstance.py:1083} INFO - Dependencies all met for <TaskInstance: dag_e2e_etl_v02.t1b_read_csv_from_local manual__2023-02-16T07:48:37.969808+00:00 [queued]>
[2023-02-16T07:48:39.676+0000] {taskinstance.py:1279} INFO - 
--------------------------------------------------------------------------------
[2023-02-16T07:48:39.684+0000] {taskinstance.py:1280} INFO - Starting attempt 1 of 1
[2023-02-16T07:48:39.687+0000] {taskinstance.py:1281} INFO - 
--------------------------------------------------------------------------------
[2023-02-16T07:48:39.715+0000] {taskinstance.py:1300} INFO - Executing <Task(PythonOperator): t1b_read_csv_from_local> on 2023-02-16 07:48:37.969808+00:00
[2023-02-16T07:48:39.756+0000] {standard_task_runner.py:55} INFO - Started process 33845 to run task
[2023-02-16T07:48:39.765+0000] {standard_task_runner.py:82} INFO - Running: ['***', 'tasks', 'run', 'dag_e2e_etl_v02', 't1b_read_csv_from_local', 'manual__2023-02-16T07:48:37.969808+00:00', '--job-id', '144', '--raw', '--subdir', 'DAGS_FOLDER/dag_e2e_etl.py', '--cfg-path', '/tmp/tmpu0syw42v']
[2023-02-16T07:48:39.770+0000] {standard_task_runner.py:83} INFO - Job 144: Subtask t1b_read_csv_from_local
[2023-02-16T07:48:39.940+0000] {task_command.py:388} INFO - Running <TaskInstance: dag_e2e_etl_v02.t1b_read_csv_from_local manual__2023-02-16T07:48:37.969808+00:00 [running]> on host 20eb5e5814e6
[2023-02-16T07:48:40.821+0000] {taskinstance.py:1509} INFO - Exporting the following env vars:
AIRFLOW_CTX_DAG_OWNER=***
AIRFLOW_CTX_DAG_ID=dag_e2e_etl_v02
AIRFLOW_CTX_TASK_ID=t1b_read_csv_from_local
AIRFLOW_CTX_EXECUTION_DATE=2023-02-16T07:48:37.969808+00:00
AIRFLOW_CTX_TRY_NUMBER=1
AIRFLOW_CTX_DAG_RUN_ID=manual__2023-02-16T07:48:37.969808+00:00
[2023-02-16T07:48:40.826+0000] {taskinstance.py:1768} ERROR - Task failed with exception
Traceback (most recent call last):
  File "/home/airflow/.local/lib/python3.7/site-packages/airflow/operators/python.py", line 175, in execute
    return_value = self.execute_callable()
  File "/home/airflow/.local/lib/python3.7/site-packages/airflow/operators/python.py", line 192, in execute_callable
    return self.python_callable(*self.op_args, **self.op_kwargs)
  File "/opt/airflow/dags/dag_e2e_etl.py", line 30, in t1b_read_csv_from_local
    df = pd.read_csv(path)
  File "/home/airflow/.local/lib/python3.7/site-packages/pandas/util/_decorators.py", line 311, in wrapper
    return func(*args, **kwargs)
  File "/home/airflow/.local/lib/python3.7/site-packages/pandas/io/parsers/readers.py", line 586, in read_csv
    return _read(filepath_or_buffer, kwds)
  File "/home/airflow/.local/lib/python3.7/site-packages/pandas/io/parsers/readers.py", line 482, in _read
    parser = TextFileReader(filepath_or_buffer, **kwds)
  File "/home/airflow/.local/lib/python3.7/site-packages/pandas/io/parsers/readers.py", line 811, in __init__
    self._engine = self._make_engine(self.engine)
  File "/home/airflow/.local/lib/python3.7/site-packages/pandas/io/parsers/readers.py", line 1040, in _make_engine
    return mapping[engine](self.f, **self.options)  # type: ignore[call-arg]
  File "/home/airflow/.local/lib/python3.7/site-packages/pandas/io/parsers/c_parser_wrapper.py", line 51, in __init__
    self._open_handles(src, kwds)
  File "/home/airflow/.local/lib/python3.7/site-packages/pandas/io/parsers/base_parser.py", line 229, in _open_handles
    errors=kwds.get("encoding_errors", "strict"),
  File "/home/airflow/.local/lib/python3.7/site-packages/pandas/io/common.py", line 707, in get_handle
    newline="",
FileNotFoundError: [Errno 2] No such file or directory: '/Users/Tanya/PycharmProjects/airflow-etl/data/titanic.csv'
[2023-02-16T07:48:40.842+0000] {taskinstance.py:1323} INFO - Marking task as FAILED. dag_id=dag_e2e_etl_v02, task_id=t1b_read_csv_from_local, execution_date=20230216T074837, start_date=20230216T074839, end_date=20230216T074840
[2023-02-16T07:48:40.873+0000] {standard_task_runner.py:105} ERROR - Failed to execute job 144 for task t1b_read_csv_from_local ([Errno 2] No such file or directory: '/Users/Tanya/PycharmProjects/airflow-etl/data/titanic.csv'; 33845)
[2023-02-16T07:48:40.934+0000] {local_task_job.py:208} INFO - Task exited with return code 1
[2023-02-16T07:48:40.962+0000] {taskinstance.py:2578} INFO - 0 downstream tasks scheduled from follow-on schedule check
