[2023-02-15T13:02:26.950+0000] {taskinstance.py:1083} INFO - Dependencies all met for <TaskInstance: dag_e2e_etl_v01.t1_read_csv manual__2023-02-15T13:02:25.473871+00:00 [queued]>
[2023-02-15T13:02:26.956+0000] {taskinstance.py:1083} INFO - Dependencies all met for <TaskInstance: dag_e2e_etl_v01.t1_read_csv manual__2023-02-15T13:02:25.473871+00:00 [queued]>
[2023-02-15T13:02:26.957+0000] {taskinstance.py:1279} INFO - 
--------------------------------------------------------------------------------
[2023-02-15T13:02:26.957+0000] {taskinstance.py:1280} INFO - Starting attempt 1 of 1
[2023-02-15T13:02:26.958+0000] {taskinstance.py:1281} INFO - 
--------------------------------------------------------------------------------
[2023-02-15T13:02:26.966+0000] {taskinstance.py:1300} INFO - Executing <Task(PythonOperator): t1_read_csv> on 2023-02-15 13:02:25.473871+00:00
[2023-02-15T13:02:26.972+0000] {standard_task_runner.py:55} INFO - Started process 7285 to run task
[2023-02-15T13:02:26.977+0000] {standard_task_runner.py:82} INFO - Running: ['***', 'tasks', 'run', 'dag_e2e_etl_v01', 't1_read_csv', 'manual__2023-02-15T13:02:25.473871+00:00', '--job-id', '120', '--raw', '--subdir', 'DAGS_FOLDER/dag_e2e_etl.py', '--cfg-path', '/tmp/tmpx3b5j5zf']
[2023-02-15T13:02:26.979+0000] {standard_task_runner.py:83} INFO - Job 120: Subtask t1_read_csv
[2023-02-15T13:02:27.078+0000] {task_command.py:388} INFO - Running <TaskInstance: dag_e2e_etl_v01.t1_read_csv manual__2023-02-15T13:02:25.473871+00:00 [running]> on host 20eb5e5814e6
[2023-02-15T13:02:27.426+0000] {taskinstance.py:1509} INFO - Exporting the following env vars:
AIRFLOW_CTX_DAG_OWNER=***
AIRFLOW_CTX_DAG_ID=dag_e2e_etl_v01
AIRFLOW_CTX_TASK_ID=t1_read_csv
AIRFLOW_CTX_EXECUTION_DATE=2023-02-15T13:02:25.473871+00:00
AIRFLOW_CTX_TRY_NUMBER=1
AIRFLOW_CTX_DAG_RUN_ID=manual__2023-02-15T13:02:25.473871+00:00
[2023-02-15T13:02:27.429+0000] {taskinstance.py:1768} ERROR - Task failed with exception
Traceback (most recent call last):
  File "/home/airflow/.local/lib/python3.7/site-packages/airflow/operators/python.py", line 175, in execute
    return_value = self.execute_callable()
  File "/home/airflow/.local/lib/python3.7/site-packages/airflow/operators/python.py", line 192, in execute_callable
    return self.python_callable(*self.op_args, **self.op_kwargs)
  File "/opt/airflow/dags/dag_e2e_etl.py", line 18, in t1_read_csv
    df = pd.read_csv(path)
NameError: name 'path' is not defined
[2023-02-15T13:02:27.441+0000] {taskinstance.py:1323} INFO - Marking task as FAILED. dag_id=dag_e2e_etl_v01, task_id=t1_read_csv, execution_date=20230215T130225, start_date=20230215T130226, end_date=20230215T130227
[2023-02-15T13:02:27.454+0000] {standard_task_runner.py:105} ERROR - Failed to execute job 120 for task t1_read_csv (name 'path' is not defined; 7285)
[2023-02-15T13:02:27.493+0000] {local_task_job.py:208} INFO - Task exited with return code 1
[2023-02-15T13:02:27.518+0000] {taskinstance.py:2578} INFO - 0 downstream tasks scheduled from follow-on schedule check
