[2023-02-14T13:41:25.506+0000] {taskinstance.py:1083} INFO - Dependencies all met for <TaskInstance: postgres_operator_dag_v1_03.insert_into_postgres_table manual__2023-02-14T13:41:23.168468+00:00 [queued]>
[2023-02-14T13:41:25.511+0000] {taskinstance.py:1083} INFO - Dependencies all met for <TaskInstance: postgres_operator_dag_v1_03.insert_into_postgres_table manual__2023-02-14T13:41:23.168468+00:00 [queued]>
[2023-02-14T13:41:25.512+0000] {taskinstance.py:1279} INFO - 
--------------------------------------------------------------------------------
[2023-02-14T13:41:25.513+0000] {taskinstance.py:1280} INFO - Starting attempt 1 of 6
[2023-02-14T13:41:25.513+0000] {taskinstance.py:1281} INFO - 
--------------------------------------------------------------------------------
[2023-02-14T13:41:25.520+0000] {taskinstance.py:1300} INFO - Executing <Task(PostgresOperator): insert_into_postgres_table> on 2023-02-14 13:41:23.168468+00:00
[2023-02-14T13:41:25.524+0000] {standard_task_runner.py:55} INFO - Started process 6411 to run task
[2023-02-14T13:41:25.527+0000] {standard_task_runner.py:82} INFO - Running: ['***', 'tasks', 'run', 'postgres_operator_dag_v1_03', 'insert_into_postgres_table', 'manual__2023-02-14T13:41:23.168468+00:00', '--job-id', '85', '--raw', '--subdir', 'DAGS_FOLDER/dag_with_postgres_operator.py', '--cfg-path', '/tmp/tmpd052lo4c']
[2023-02-14T13:41:25.530+0000] {standard_task_runner.py:83} INFO - Job 85: Subtask insert_into_postgres_table
[2023-02-14T13:41:25.581+0000] {task_command.py:388} INFO - Running <TaskInstance: postgres_operator_dag_v1_03.insert_into_postgres_table manual__2023-02-14T13:41:23.168468+00:00 [running]> on host 01550fe0586b
[2023-02-14T13:41:25.635+0000] {taskinstance.py:1509} INFO - Exporting the following env vars:
AIRFLOW_CTX_DAG_OWNER=tlysenko
AIRFLOW_CTX_DAG_ID=postgres_operator_dag_v1_03
AIRFLOW_CTX_TASK_ID=insert_into_postgres_table
AIRFLOW_CTX_EXECUTION_DATE=2023-02-14T13:41:23.168468+00:00
AIRFLOW_CTX_TRY_NUMBER=1
AIRFLOW_CTX_DAG_RUN_ID=manual__2023-02-14T13:41:23.168468+00:00
[2023-02-14T13:41:25.636+0000] {sql.py:254} INFO - Executing: 
            INSERT INTO dag_runs(dt, dag_id) values(2023-02-14, postgres_operator_dag_v1_03)
        
[2023-02-14T13:41:25.645+0000] {base.py:73} INFO - Using connection ID 'postgres_localhost' for task execution.
[2023-02-14T13:41:25.779+0000] {base.py:73} INFO - Using connection ID 'postgres_localhost' for task execution.
[2023-02-14T13:41:25.785+0000] {sql.py:375} INFO - Running statement: 
            INSERT INTO dag_runs(dt, dag_id) values(2023-02-14, postgres_operator_dag_v1_03)
        , parameters: None
[2023-02-14T13:41:25.789+0000] {taskinstance.py:1768} ERROR - Task failed with exception
Traceback (most recent call last):
  File "/home/airflow/.local/lib/python3.7/site-packages/airflow/providers/common/sql/operators/sql.py", line 266, in execute
    **extra_kwargs,
  File "/home/airflow/.local/lib/python3.7/site-packages/airflow/providers/common/sql/hooks/sql.py", line 349, in run
    self._run_command(cur, sql_statement, parameters)
  File "/home/airflow/.local/lib/python3.7/site-packages/airflow/providers/common/sql/hooks/sql.py", line 380, in _run_command
    cur.execute(sql_statement)
psycopg2.errors.UndefinedColumn: column "postgres_operator_dag_v1_03" does not exist
LINE 2: ...SERT INTO dag_runs(dt, dag_id) values(2023-02-14, postgres_o...
                                                             ^

[2023-02-14T13:41:25.800+0000] {taskinstance.py:1323} INFO - Marking task as UP_FOR_RETRY. dag_id=postgres_operator_dag_v1_03, task_id=insert_into_postgres_table, execution_date=20230214T134123, start_date=20230214T134125, end_date=20230214T134125
[2023-02-14T13:41:25.811+0000] {standard_task_runner.py:105} ERROR - Failed to execute job 85 for task insert_into_postgres_table (column "postgres_operator_dag_v1_03" does not exist
LINE 2: ...SERT INTO dag_runs(dt, dag_id) values(2023-02-14, postgres_o...
                                                             ^
; 6411)
[2023-02-14T13:41:25.865+0000] {local_task_job.py:208} INFO - Task exited with return code 1
[2023-02-14T13:41:25.884+0000] {taskinstance.py:2578} INFO - 0 downstream tasks scheduled from follow-on schedule check
