[2023-02-22T16:21:57.119+0000] {taskinstance.py:1083} INFO - Dependencies all met for <TaskInstance: csv_from_s3_to_s3_v01.test_get_file_from_s3 manual__2023-02-22T16:21:55.550221+00:00 [queued]>
[2023-02-22T16:21:57.130+0000] {taskinstance.py:1083} INFO - Dependencies all met for <TaskInstance: csv_from_s3_to_s3_v01.test_get_file_from_s3 manual__2023-02-22T16:21:55.550221+00:00 [queued]>
[2023-02-22T16:21:57.131+0000] {taskinstance.py:1279} INFO - 
--------------------------------------------------------------------------------
[2023-02-22T16:21:57.131+0000] {taskinstance.py:1280} INFO - Starting attempt 1 of 1
[2023-02-22T16:21:57.141+0000] {taskinstance.py:1281} INFO - 
--------------------------------------------------------------------------------
[2023-02-22T16:21:57.162+0000] {taskinstance.py:1300} INFO - Executing <Task(PythonOperator): test_get_file_from_s3> on 2023-02-22 16:21:55.550221+00:00
[2023-02-22T16:21:57.170+0000] {standard_task_runner.py:55} INFO - Started process 8385 to run task
[2023-02-22T16:21:57.177+0000] {standard_task_runner.py:82} INFO - Running: ['***', 'tasks', 'run', 'csv_from_s3_to_s3_v01', 'test_get_file_from_s3', 'manual__2023-02-22T16:21:55.550221+00:00', '--job-id', '214', '--raw', '--subdir', 'DAGS_FOLDER/dag_cleaning_via_s3.py', '--cfg-path', '/tmp/tmp1o244376']
[2023-02-22T16:21:57.180+0000] {standard_task_runner.py:83} INFO - Job 214: Subtask test_get_file_from_s3
[2023-02-22T16:21:57.289+0000] {task_command.py:388} INFO - Running <TaskInstance: csv_from_s3_to_s3_v01.test_get_file_from_s3 manual__2023-02-22T16:21:55.550221+00:00 [running]> on host 22976f44c0e9
[2023-02-22T16:21:57.357+0000] {taskinstance.py:1509} INFO - Exporting the following env vars:
AIRFLOW_CTX_DAG_OWNER=***
AIRFLOW_CTX_DAG_ID=csv_from_s3_to_s3_v01
AIRFLOW_CTX_TASK_ID=test_get_file_from_s3
AIRFLOW_CTX_EXECUTION_DATE=2023-02-22T16:21:55.550221+00:00
AIRFLOW_CTX_TRY_NUMBER=1
AIRFLOW_CTX_DAG_RUN_ID=manual__2023-02-22T16:21:55.550221+00:00
[2023-02-22T16:21:57.359+0000] {logging_mixin.py:137} INFO - file name titanic.csv 
[2023-02-22T16:21:57.369+0000] {base.py:73} INFO - Using connection ID 'AWS' for task execution.
[2023-02-22T16:21:57.371+0000] {connection_wrapper.py:334} INFO - AWS Connection (conn_id='AWS', conn_type='aws') credentials retrieved from login and password.
[2023-02-22T16:21:58.304+0000] {taskinstance.py:1768} ERROR - Task failed with exception
Traceback (most recent call last):
  File "/home/airflow/.local/lib/python3.7/site-packages/airflow/operators/python.py", line 175, in execute
    return_value = self.execute_callable()
  File "/home/airflow/.local/lib/python3.7/site-packages/airflow/operators/python.py", line 192, in execute_callable
    return self.python_callable(*self.op_args, **self.op_kwargs)
  File "/opt/airflow/dags/dag_cleaning_via_s3.py", line 38, in get_file_from_s3
    s3_object = s3_hook.get_key(file_name, s3_bucket_name)
  File "/home/airflow/.local/lib/python3.7/site-packages/airflow/providers/amazon/aws/hooks/s3.py", line 99, in wrapper
    return func(*bound_args.args, **bound_args.kwargs)
  File "/home/airflow/.local/lib/python3.7/site-packages/airflow/providers/amazon/aws/hooks/s3.py", line 70, in wrapper
    return func(*bound_args.args, **bound_args.kwargs)
  File "/home/airflow/.local/lib/python3.7/site-packages/airflow/providers/amazon/aws/hooks/s3.py", line 501, in get_key
    obj.load()
  File "/home/airflow/.local/lib/python3.7/site-packages/boto3/resources/factory.py", line 564, in do_action
    response = action(self, *args, **kwargs)
  File "/home/airflow/.local/lib/python3.7/site-packages/boto3/resources/action.py", line 88, in __call__
    response = getattr(parent.meta.client, operation_name)(*args, **params)
  File "/home/airflow/.local/lib/python3.7/site-packages/botocore/client.py", line 530, in _api_call
    return self._make_api_call(operation_name, kwargs)
  File "/home/airflow/.local/lib/python3.7/site-packages/botocore/client.py", line 960, in _make_api_call
    raise error_class(parsed_response, operation_name)
botocore.exceptions.ClientError: An error occurred (404) when calling the HeadObject operation: Not Found
[2023-02-22T16:21:58.325+0000] {taskinstance.py:1323} INFO - Marking task as FAILED. dag_id=csv_from_s3_to_s3_v01, task_id=test_get_file_from_s3, execution_date=20230222T162155, start_date=20230222T162157, end_date=20230222T162158
[2023-02-22T16:21:58.336+0000] {standard_task_runner.py:105} ERROR - Failed to execute job 214 for task test_get_file_from_s3 (An error occurred (404) when calling the HeadObject operation: Not Found; 8385)
[2023-02-22T16:21:58.364+0000] {local_task_job.py:208} INFO - Task exited with return code 1
[2023-02-22T16:21:58.391+0000] {taskinstance.py:2578} INFO - 0 downstream tasks scheduled from follow-on schedule check
