[2023-02-22T15:54:18.763+0000] {taskinstance.py:1083} INFO - Dependencies all met for <TaskInstance: csv_from_s3_to_s3_v01.test_get_file_from_s3 manual__2023-02-22T15:54:17.358227+00:00 [queued]>
[2023-02-22T15:54:18.773+0000] {taskinstance.py:1083} INFO - Dependencies all met for <TaskInstance: csv_from_s3_to_s3_v01.test_get_file_from_s3 manual__2023-02-22T15:54:17.358227+00:00 [queued]>
[2023-02-22T15:54:18.774+0000] {taskinstance.py:1279} INFO - 
--------------------------------------------------------------------------------
[2023-02-22T15:54:18.775+0000] {taskinstance.py:1280} INFO - Starting attempt 1 of 1
[2023-02-22T15:54:18.775+0000] {taskinstance.py:1281} INFO - 
--------------------------------------------------------------------------------
[2023-02-22T15:54:18.789+0000] {taskinstance.py:1300} INFO - Executing <Task(PythonOperator): test_get_file_from_s3> on 2023-02-22 15:54:17.358227+00:00
[2023-02-22T15:54:18.842+0000] {standard_task_runner.py:82} INFO - Running: ['***', 'tasks', 'run', 'csv_from_s3_to_s3_v01', 'test_get_file_from_s3', 'manual__2023-02-22T15:54:17.358227+00:00', '--job-id', '185', '--raw', '--subdir', 'DAGS_FOLDER/dag_cleaning_via_s3.py', '--cfg-path', '/tmp/tmp4sx_w_z1']
[2023-02-22T15:54:18.822+0000] {standard_task_runner.py:55} INFO - Started process 4375 to run task
[2023-02-22T15:54:18.853+0000] {standard_task_runner.py:83} INFO - Job 185: Subtask test_get_file_from_s3
[2023-02-22T15:54:18.981+0000] {task_command.py:388} INFO - Running <TaskInstance: csv_from_s3_to_s3_v01.test_get_file_from_s3 manual__2023-02-22T15:54:17.358227+00:00 [running]> on host 22976f44c0e9
[2023-02-22T15:54:19.190+0000] {taskinstance.py:1509} INFO - Exporting the following env vars:
AIRFLOW_CTX_DAG_OWNER=***
AIRFLOW_CTX_DAG_ID=csv_from_s3_to_s3_v01
AIRFLOW_CTX_TASK_ID=test_get_file_from_s3
AIRFLOW_CTX_EXECUTION_DATE=2023-02-22T15:54:17.358227+00:00
AIRFLOW_CTX_TRY_NUMBER=1
AIRFLOW_CTX_DAG_RUN_ID=manual__2023-02-22T15:54:17.358227+00:00
[2023-02-22T15:54:19.195+0000] {taskinstance.py:1768} ERROR - Task failed with exception
Traceback (most recent call last):
  File "/home/airflow/.local/lib/python3.7/site-packages/airflow/operators/python.py", line 175, in execute
    return_value = self.execute_callable()
  File "/home/airflow/.local/lib/python3.7/site-packages/airflow/operators/python.py", line 192, in execute_callable
    return self.python_callable(*self.op_args, **self.op_kwargs)
TypeError: get_file_from_s3() missing 1 required positional argument: 'file_name'
[2023-02-22T15:54:19.217+0000] {taskinstance.py:1323} INFO - Marking task as FAILED. dag_id=csv_from_s3_to_s3_v01, task_id=test_get_file_from_s3, execution_date=20230222T155417, start_date=20230222T155418, end_date=20230222T155419
[2023-02-22T15:54:19.258+0000] {standard_task_runner.py:105} ERROR - Failed to execute job 185 for task test_get_file_from_s3 (get_file_from_s3() missing 1 required positional argument: 'file_name'; 4375)
[2023-02-22T15:54:19.359+0000] {local_task_job.py:208} INFO - Task exited with return code 1
[2023-02-22T15:54:19.425+0000] {taskinstance.py:2578} INFO - 0 downstream tasks scheduled from follow-on schedule check
