[2023-02-16T07:28:31.813+0000] {taskinstance.py:1083} INFO - Dependencies all met for <TaskInstance: dag_e2e_etl_v02.t1a_read_csv_from_web scheduled__2023-02-15T00:00:00+00:00 [queued]>
[2023-02-16T07:28:31.841+0000] {taskinstance.py:1083} INFO - Dependencies all met for <TaskInstance: dag_e2e_etl_v02.t1a_read_csv_from_web scheduled__2023-02-15T00:00:00+00:00 [queued]>
[2023-02-16T07:28:31.842+0000] {taskinstance.py:1279} INFO - 
--------------------------------------------------------------------------------
[2023-02-16T07:28:31.843+0000] {taskinstance.py:1280} INFO - Starting attempt 1 of 1
[2023-02-16T07:28:31.843+0000] {taskinstance.py:1281} INFO - 
--------------------------------------------------------------------------------
[2023-02-16T07:28:31.857+0000] {taskinstance.py:1300} INFO - Executing <Task(PythonOperator): t1a_read_csv_from_web> on 2023-02-15 00:00:00+00:00
[2023-02-16T07:28:31.889+0000] {standard_task_runner.py:55} INFO - Started process 31057 to run task
[2023-02-16T07:28:31.905+0000] {standard_task_runner.py:82} INFO - Running: ['***', 'tasks', 'run', 'dag_e2e_etl_v02', 't1a_read_csv_from_web', 'scheduled__2023-02-15T00:00:00+00:00', '--job-id', '128', '--raw', '--subdir', 'DAGS_FOLDER/dag_e2e_etl.py', '--cfg-path', '/tmp/tmpo1ocztv8']
[2023-02-16T07:28:31.913+0000] {standard_task_runner.py:83} INFO - Job 128: Subtask t1a_read_csv_from_web
[2023-02-16T07:28:32.240+0000] {task_command.py:388} INFO - Running <TaskInstance: dag_e2e_etl_v02.t1a_read_csv_from_web scheduled__2023-02-15T00:00:00+00:00 [running]> on host 20eb5e5814e6
[2023-02-16T07:28:34.804+0000] {taskinstance.py:1509} INFO - Exporting the following env vars:
AIRFLOW_CTX_DAG_OWNER=***
AIRFLOW_CTX_DAG_ID=dag_e2e_etl_v02
AIRFLOW_CTX_TASK_ID=t1a_read_csv_from_web
AIRFLOW_CTX_EXECUTION_DATE=2023-02-15T00:00:00+00:00
AIRFLOW_CTX_TRY_NUMBER=1
AIRFLOW_CTX_DAG_RUN_ID=scheduled__2023-02-15T00:00:00+00:00
[2023-02-16T07:28:36.571+0000] {taskinstance.py:1768} ERROR - Task failed with exception
Traceback (most recent call last):
  File "/home/airflow/.local/lib/python3.7/site-packages/airflow/operators/python.py", line 175, in execute
    return_value = self.execute_callable()
  File "/home/airflow/.local/lib/python3.7/site-packages/airflow/operators/python.py", line 192, in execute_callable
    return self.python_callable(*self.op_args, **self.op_kwargs)
  File "/opt/airflow/dags/dag_e2e_etl.py", line 24, in t1a_read_csv_from_web
    write_file_to_local('t1a.csv', df)
  File "/opt/airflow/dags/dag_e2e_etl.py", line 18, in write_file_to_local
    df.to_csv(path + filename, index=False)
  File "/home/airflow/.local/lib/python3.7/site-packages/pandas/core/generic.py", line 3482, in to_csv
    storage_options=storage_options,
  File "/home/airflow/.local/lib/python3.7/site-packages/pandas/io/formats/format.py", line 1105, in to_csv
    csv_formatter.save()
  File "/home/airflow/.local/lib/python3.7/site-packages/pandas/io/formats/csvs.py", line 243, in save
    storage_options=self.storage_options,
  File "/home/airflow/.local/lib/python3.7/site-packages/pandas/io/common.py", line 707, in get_handle
    newline="",
FileNotFoundError: [Errno 2] No such file or directory: '/Users/Tanya/PycharmProjects/airflow-etl/data/t1a.csv'
[2023-02-16T07:28:36.765+0000] {taskinstance.py:1323} INFO - Marking task as FAILED. dag_id=dag_e2e_etl_v02, task_id=t1a_read_csv_from_web, execution_date=20230215T000000, start_date=20230216T072831, end_date=20230216T072836
[2023-02-16T07:28:36.867+0000] {standard_task_runner.py:105} ERROR - Failed to execute job 128 for task t1a_read_csv_from_web ([Errno 2] No such file or directory: '/Users/Tanya/PycharmProjects/airflow-etl/data/t1a.csv'; 31057)
[2023-02-16T07:28:37.163+0000] {local_task_job.py:208} INFO - Task exited with return code 1
[2023-02-16T07:28:37.216+0000] {taskinstance.py:2578} INFO - 0 downstream tasks scheduled from follow-on schedule check
