[2023-02-14T10:08:15.152+0000] {taskinstance.py:1083} INFO - Dependencies all met for <TaskInstance: dag_with_task_flow_v1.0.get_name manual__2023-02-14T10:06:13.381573+00:00 [queued]>
[2023-02-14T10:08:15.159+0000] {taskinstance.py:1083} INFO - Dependencies all met for <TaskInstance: dag_with_task_flow_v1.0.get_name manual__2023-02-14T10:06:13.381573+00:00 [queued]>
[2023-02-14T10:08:15.159+0000] {taskinstance.py:1279} INFO - 
--------------------------------------------------------------------------------
[2023-02-14T10:08:15.160+0000] {taskinstance.py:1280} INFO - Starting attempt 2 of 6
[2023-02-14T10:08:15.160+0000] {taskinstance.py:1281} INFO - 
--------------------------------------------------------------------------------
[2023-02-14T10:08:15.168+0000] {taskinstance.py:1300} INFO - Executing <Task(_PythonDecoratedOperator): get_name> on 2023-02-14 10:06:13.381573+00:00
[2023-02-14T10:08:15.172+0000] {standard_task_runner.py:55} INFO - Started process 30708 to run task
[2023-02-14T10:08:15.176+0000] {standard_task_runner.py:82} INFO - Running: ['***', 'tasks', 'run', 'dag_with_task_flow_v1.0', 'get_name', 'manual__2023-02-14T10:06:13.381573+00:00', '--job-id', '28', '--raw', '--subdir', 'DAGS_FOLDER/dag_with_task_flow.py', '--cfg-path', '/tmp/tmpbjh_zbip']
[2023-02-14T10:08:15.178+0000] {standard_task_runner.py:83} INFO - Job 28: Subtask get_name
[2023-02-14T10:08:15.234+0000] {task_command.py:388} INFO - Running <TaskInstance: dag_with_task_flow_v1.0.get_name manual__2023-02-14T10:06:13.381573+00:00 [running]> on host 38744fc0668d
[2023-02-14T10:08:15.287+0000] {taskinstance.py:1509} INFO - Exporting the following env vars:
AIRFLOW_CTX_DAG_OWNER=tlysenko
AIRFLOW_CTX_DAG_ID=dag_with_task_flow_v1.0
AIRFLOW_CTX_TASK_ID=get_name
AIRFLOW_CTX_EXECUTION_DATE=2023-02-14T10:06:13.381573+00:00
AIRFLOW_CTX_TRY_NUMBER=2
AIRFLOW_CTX_DAG_RUN_ID=manual__2023-02-14T10:06:13.381573+00:00
[2023-02-14T10:08:15.289+0000] {taskinstance.py:1768} ERROR - Task failed with exception
Traceback (most recent call last):
  File "/home/airflow/.local/lib/python3.7/site-packages/airflow/decorators/base.py", line 217, in execute
    return_value = super().execute(context)
  File "/home/airflow/.local/lib/python3.7/site-packages/airflow/operators/python.py", line 175, in execute
    return_value = self.execute_callable()
  File "/home/airflow/.local/lib/python3.7/site-packages/airflow/operators/python.py", line 192, in execute_callable
    return self.python_callable(*self.op_args, **self.op_kwargs)
  File "/opt/airflow/dags/dag_with_task_flow.py", line 17, in get_name
    return Jerry
NameError: name 'Jerry' is not defined
[2023-02-14T10:08:15.299+0000] {taskinstance.py:1323} INFO - Marking task as UP_FOR_RETRY. dag_id=dag_with_task_flow_v1.0, task_id=get_name, execution_date=20230214T100613, start_date=20230214T100815, end_date=20230214T100815
[2023-02-14T10:08:15.306+0000] {standard_task_runner.py:105} ERROR - Failed to execute job 28 for task get_name (name 'Jerry' is not defined; 30708)
[2023-02-14T10:08:15.353+0000] {local_task_job.py:208} INFO - Task exited with return code 1
[2023-02-14T10:08:15.376+0000] {taskinstance.py:2578} INFO - 0 downstream tasks scheduled from follow-on schedule check
